<?xml version="1.0"?>
<robot xmlns:xacro="http://www.ros.org/wiki/xacro" name="robot_name">
    <xacro:include filename="inertial.xacro"/>
    <xacro:property name="mass" value="1.0"/>
    <xacro:property name="cx" value="0.1"/>
    <xacro:property name="cy" value="0.1"/>
    <xacro:property name="cz" value="0.1"/>
    <link name="base_link"/>

    <joint name="wbase_joint" type="fixed">
        <parent link="base_link"/>
        <child link="base_chasis_link"/>
        <origin xyz="0 0 0" rpy="0 0 0"/>
        <axis xyz="0 0 0"/>
    </joint>

    <link name="base_chasis_link">
        <visual>
            <origin xyz="0 0 0" rpy="0 0 0"/>
            <geometry>
                <box size="${cx} ${cy} ${cz}"/> 
                <!-- <box size="0.1 0.1 0.1"/> -->
            </geometry>
        </visual>
        <xacro:inertial_box mass="0.5" x="${cx}" y="${cy}" z="${cz}">
            <origin xyz="0 0 0" rpy="0 0 0"/>
        </xacro:inertial_box>
    </link>
        
    <joint name="wheel_joint" type="continuous">
        <parent link="base_link"/>
        <child link="wheel_link"/>
        <origin xyz="0 0.06 0" rpy="1.56 0 0"/>
        <axis xyz="0 0 1"/>
    </joint>

    <link name="wheel_link">
        <visual>
            <origin xyz="0 0 0" rpy="0 0 0"/>
            <geometry>
                <cylinder radius="0.05" length="0.02"/> 
            </geometry>
        </visual>
    </link>

    <joint name="wheel_joint1" type="continuous">
        <parent link="base_link"/>
        <child link="wheel_link1"/>
        <origin xyz="0 -0.06 0" rpy="1.56 0 0"/>
        <axis xyz="0 0 1"/>
    </joint>

    <link name="wheel_link1">
        <visual>
            <origin xyz="0 0 0" rpy="0 0 0"/>
            <geometry>
            <cylinder radius="0.05" length="0.02"/> 
            </geometry>
        </visual>
        <collision>
            <origin xyz="0 0 0" rpy="0 0 0"/>
            <geometry>
            <cylinder radius="0.05" length="0.02"/> 
            </geometry>
        </collision>
    </link>

</robot>